[2025-07-15T14:03:00.719+0000] {taskinstance.py:1956} INFO - Dependencies all met for dep_context=non-requeueable deps ti=<TaskInstance: prepare_raw_data_daily.extract_one_day_to_unprocessed scheduled__2025-07-15T14:02:00+00:00 [queued]>
[2025-07-15T14:03:00.724+0000] {taskinstance.py:1956} INFO - Dependencies all met for dep_context=requeueable deps ti=<TaskInstance: prepare_raw_data_daily.extract_one_day_to_unprocessed scheduled__2025-07-15T14:02:00+00:00 [queued]>
[2025-07-15T14:03:00.724+0000] {taskinstance.py:2170} INFO - Starting attempt 1 of 2
[2025-07-15T14:03:00.732+0000] {taskinstance.py:2191} INFO - Executing <Task(PythonOperator): extract_one_day_to_unprocessed> on 2025-07-15 14:02:00+00:00
[2025-07-15T14:03:00.736+0000] {standard_task_runner.py:60} INFO - Started process 2218 to run task
[2025-07-15T14:03:00.738+0000] {standard_task_runner.py:87} INFO - Running: ['***', 'tasks', 'run', 'prepare_raw_data_daily', 'extract_one_day_to_unprocessed', 'scheduled__2025-07-15T14:02:00+00:00', '--job-id', '588', '--raw', '--subdir', 'DAGS_FOLDER/extract_daily_to_s3.py', '--cfg-path', '/tmp/tmpsclyx9dc']
[2025-07-15T14:03:00.740+0000] {standard_task_runner.py:88} INFO - Job 588: Subtask extract_one_day_to_unprocessed
[2025-07-15T14:03:00.771+0000] {task_command.py:423} INFO - Running <TaskInstance: prepare_raw_data_daily.extract_one_day_to_unprocessed scheduled__2025-07-15T14:02:00+00:00 [running]> on host 9b64cb4f6e82
[2025-07-15T14:03:00.824+0000] {taskinstance.py:2480} INFO - Exporting env vars: AIRFLOW_CTX_DAG_OWNER='***' AIRFLOW_CTX_DAG_ID='prepare_raw_data_daily' AIRFLOW_CTX_TASK_ID='extract_one_day_to_unprocessed' AIRFLOW_CTX_EXECUTION_DATE='2025-07-15T14:02:00+00:00' AIRFLOW_CTX_TRY_NUMBER='1' AIRFLOW_CTX_DAG_RUN_ID='scheduled__2025-07-15T14:02:00+00:00'
[2025-07-15T14:03:00.830+0000] {logging_mixin.py:188} INFO - Loading raw CSV files...
[2025-07-15T14:03:00.835+0000] {taskinstance.py:2698} ERROR - Task failed with exception
Traceback (most recent call last):
  File "/home/airflow/.local/lib/python3.8/site-packages/airflow/models/taskinstance.py", line 433, in _execute_task
    result = execute_callable(context=context, **execute_callable_kwargs)
  File "/home/airflow/.local/lib/python3.8/site-packages/airflow/operators/python.py", line 199, in execute
    return_value = self.execute_callable()
  File "/home/airflow/.local/lib/python3.8/site-packages/airflow/operators/python.py", line 216, in execute_callable
    return self.python_callable(*self.op_args, **self.op_kwargs)
  File "/opt/airflow/data_generator/extract_raw_to_s3_daily.py", line 73, in extract_one_day_to_unprocessed
    raw_online = read_csv_from_s3(MINIO_RAW, ONLINE_FILE_NAME, TMSTMP)
  File "/opt/airflow/data_generator/extract_raw_to_s3_daily.py", line 35, in read_csv_from_s3
    obj = S3.get_object(Bucket=bucket, Key=key)
  File "/home/airflow/.local/lib/python3.8/site-packages/botocore/client.py", line 553, in _api_call
    return self._make_api_call(operation_name, kwargs)
  File "/home/airflow/.local/lib/python3.8/site-packages/botocore/client.py", line 1009, in _make_api_call
    raise error_class(parsed_response, operation_name)
botocore.errorfactory.NoSuchBucket: An error occurred (NoSuchBucket) when calling the GetObject operation: The specified bucket does not exist
[2025-07-15T14:03:00.844+0000] {taskinstance.py:1138} INFO - Marking task as UP_FOR_RETRY. dag_id=prepare_raw_data_daily, task_id=extract_one_day_to_unprocessed, execution_date=20250715T140200, start_date=20250715T140300, end_date=20250715T140300
[2025-07-15T14:03:00.850+0000] {standard_task_runner.py:107} ERROR - Failed to execute job 588 for task extract_one_day_to_unprocessed (An error occurred (NoSuchBucket) when calling the GetObject operation: The specified bucket does not exist; 2218)
[2025-07-15T14:03:00.870+0000] {local_task_job_runner.py:234} INFO - Task exited with return code 1
[2025-07-15T14:03:00.881+0000] {taskinstance.py:3280} INFO - 0 downstream tasks scheduled from follow-on schedule check
